Workbook

Sheet Parametros
A1: Parámetros de la base de datos (celdas amarillas = supuestos editables)
A3: Parámetro | B3: Valor
A4: Peso Calidad del servicio en IDP | B4: 0.35
A5: Peso OTIF (entregas a tiempo y completas) en IDP | B5: 0.3
A6: Peso Cumplimiento de proceso en IDP | B6: 0.2
A7: Peso (1 - Tasa de rechazo) en IDP | B7: 0.15
A8: Presupuesto total anual de compras a asignar (MXN) | B8: 1200000000
A9: Tasa de referencia promedio 2023-2025 (simulada) | B9: =AVERAGE('Tasa Referencia'!B2:B37) -> 0.098783333 | C9: Calculada: promedio de la hoja Tasa_Referencia. La tasa de cada proveedor = referencia + spread del proveedor + choque mensual.
A10: Participación mínima por proveedor seleccionado | B10: 0.002
A11: Participación máxima por proveedor | B11: 0.08
A12: Número mínimo de proveedores por giro | B12: 2
A13: Calificación IDP mínima aceptable (0-100) | B13: 75
A14: Suma de pesos IDP (debe ser 100%) | B14: =SUM(B4:B7) -> 1
A17: Límites de participación por giro (restricciones sugeridas)
A18: Giro | B18: Código | C18: Participación mínima | D18: Participación máxima | E18: Spread de riesgo por giro
A19: Materias primas | B19: MP | C19: 0.15 | D19: 0.35 | E19: 0.012
A20: Empaque y embalaje | B20: EE | C20: 0.03 | D20: 0.12 | E20: 0.01
A21: Transporte y logística | B21: TL | C21: 0.05 | D21: 0.18 | E21: 0.022
A22: Mantenimiento industrial | B22: MI | C22: 0.02 | D22: 0.1 | E22: 0.015
A23: Tecnologías de la información | B23: TI | C23: 0.03 | D23: 0.12 | E23: 0.018
A24: Refacciones y componentes | B24: RC | C24: 0.03 | D24: 0.12 | E24: 0.014
A25: Energía y combustibles | B25: EC | C25: 0.08 | D25: 0.25 | E25: 0.028
A26: Químicos e insumos industriales | B26: QI | C26: 0.04 | D26: 0.15 | E26: 0.02
A27: Servicios generales (limpieza y seguridad) | B27: SG | C27: 0.01 | D27: 0.06 | E27: 0.008
A28: Servicios profesionales y consultoría | B28: SP | C28: 0.01 | D28: 0.06 | E28: 0.011
A29: Totales | C29: =SUM(C19:C28) -> 0.45 | D29: =SUM(D19:D28) -> 1.51
A31: Componentes del spread de riesgo por proveedor (se suman a la tasa de referencia)
A33: Criticidad | B33: Spread
A34: Alta | B34: 0.01
A35: Media | B35: 0.005
A36: Baja | B36: 0
A38: Proveedor_Unico | B38: Spread
A39: Sí | B39: 0.0125
A40: No | B40: 0
A42: Certificacion_ISO | B42: Spread
A43: ISO 9001 | B43: 0
A44: ISO 9001 / 14001 | B44: -0.0025
A45: ISO 45001 | B45: 0
A46: Ninguna | B46: 0.01
A48: Plazo_Pago_Dias | B48: Spread
...

Sheet Catalogo Proveedores
A1: ID Proveedor | B1: Razon Social | C1: Giro | D1: Codigo Giro | E1: Estado | F1: Anio Alta | G1: Tipo Contrato | H1: Criticidad | I1: Proveedor Unico | J1: Certificacion ISO | K1: Plazo Pago Dias | L1: Monto Contrato Base 2023 MXN | M1: Ajuste Especifico Tasa | N1: Spread Riesgo Proveedor
A2: PRV-001 | B2: Comercializadora Aceros del Norte S. de R.L. de C.V. | C2: Materias primas | D2: MP | E2: Querétaro | F2: 2015 | G2: Marco anual | H2: Media | I2: No | J2: ISO 9001 | K2: 45 | L2: 18134000 | M2: 0.0017 | N2: =INDEX(Parametros!$E$19:$E$28,MATCH(D2,Parametros!$B$19:$B$28,0))+INDEX(Parametros!$B$34:$B$36,MATCH(H2,Parametros!$A$34:$A$36,0))+INDEX(Parametros!$B$39:$B$40,MATCH(I2,Parametros!$A$39:$A$40,0))+INDEX(Parametros!$B$43:$B$46,MATCH(J2,Parametros!$A$43:$A$46,0))+INDEX(Parametros!$B$49:$B$52,MATCH(K2,Parametros!$A$49:$A$52,0))+M2 -> 0.0212
A3: PRV-002 | B3: Distribuidora Resinas de Occidente S.A.P.I. de C.V. | C3: Materias primas | D3: MP | E3: San Luis Potosí | F3: 2010 | G3: Servicio recurrente | H3: Baja | I3: No | J3: ISO 9001 | K3: 30 | L3: 55289000 | M3: -0.0023 | N3: =INDEX(Parametros!$E$19:$E$28,MATCH(D3,Parametros!$B$19:$B$28,0))+INDEX(Parametros!$B$34:$B$36,MATCH(H3,Parametros!$A$34:$A$36,0))+INDEX(Parametros!$B$39:$B$40,MATCH(I3,Parametros!$A$39:$A$40,0))+INDEX(Parametros!$B$43:$B$46,MATCH(J3,Parametros!$A$43:$A$46,0))+INDEX(Parametros!$B$49:$B$52,MATCH(K3,Parametros!$A$49:$A$52,0))+M3 -> 0.0097
A4: PRV-003 | B4: Corporativo Metales Unidos S.A. de C.V. | C4: Materias primas | D4: MP | E4: Querétaro | F4: 2019 | G4: Plurianual | H4: Baja | I4: No | J4: ISO 9001 | K4: 90 | L4: 44674000 | M4: 0.0106 | N4: =INDEX(Parametros!$E$19:$E$28,MATCH(D4,Parametros!$B$19:$B$28,0))+INDEX(Parametros!$B$34:$B$36,MATCH(H4,Parametros!$A$34:$A$36,0))+INDEX(Parametros!$B$39:$B$40,MATCH(I4,Parametros!$A$39:$A$40,0))+INDEX(Parametros!$B$43:$B$46,MATCH(J4,Parametros!$A$43:$A$46,0))+INDEX(Parametros!$B$49:$B$52,MATCH(K4,Parametros!$A$49:$A$52,0))+M4 -> 0.0326
A5: PRV-004 | B5: Proveedora Polímeros del Golfo S. de R.L. de C.V. | C5: Materias primas | D5: MP | E5: Jalisco | F5: 2018 | G5: Marco anual | H5: Alta | I5: No | J5: Ninguna | K5: 60 | L5: 20186000 | M5: -0.0064 | N5: =INDEX(Parametros!$E$19:$E$28,MATCH(D5,Parametros!$B$19:$B$28,0))+INDEX(Parametros!$B$34:$B$36,MATCH(H5,Parametros!$A$34:$A$36,0))+INDEX(Parametros!$B$39:$B$40,MATCH(I5,Parametros!$A$39:$A$40,0))+INDEX(Parametros!$B$43:$B$46,MATCH(J5,Parametros!$A$43:$A$46,0))+INDEX(Parametros!$B$49:$B$52,MATCH(K5,Parametros!$A$49:$A$52,0))+M5 -> 0.0306
A6: PRV-005 | B6: Operadora Minerales Integrales S.A.P.I. de C.V. | C6: Materias primas | D6: MP | E6: Guanajuato | F6: 2015 | G6: Por pedido | H6: Alta | I6: No | J6: ISO 9001 | K6: 45 | L6: 22762000 | M6: 0.0026 | N6: =INDEX(Parametros!$E$19:$E$28,MATCH(D6,Parametros!$B$19:$B$28,0))+INDEX(Parametros!$B$34:$B$36,MATCH(H6,Parametros!$A$34:$A$36,0))+INDEX(Parametros!$B$39:$B$40,MATCH(I6,Parametros!$A$39:$A$40,0))+INDEX(Parametros!$B$43:$B$46,MATCH(J6,Parametros!$A$43:$A$46,0))+INDEX(Parametros!$B$49:$B$52,MATCH(K6,Parametros!$A$49:$A$52,0))+M6 -> 0.0271
A7: PRV-006 | B7: Comercializadora Aleaciones del Norte S.A. de C.V. | C7: Materias primas | D7: MP | E7: Querétaro | F7: 2020 | G7: Marco anual | H7: Media | I7: No | J7: ISO 9001 / 14001 | K7: 90 | L7: 56962000 | M7: -0.0006 | N7: =INDEX(Parametros!$E$19:$E$28,MATCH(D7,Parametros!$B$19:$B$28,0))+INDEX(Parametros!$B$34:$B$36,MATCH(H7,Parametros!$A$34:$A$36,0))+INDEX(Parametros!$B$39:$B$40,MATCH(I7,Parametros!$A$39:$A$40,0))+INDEX(Parametros!$B$43:$B$46,MATCH(J7,Parametros!$A$43:$A$46,0))+INDEX(Parametros!$B$49:$B$52,MATCH(K7,Parametros!$A$49:$A$52,0))+M7 -> 0.0239
A8: PRV-007 | B8: Distribuidora Materiales de Occidente S. de R.L. de C.V. | C8: Materias primas | D8: MP | E8: Nuevo León | F8: 2019 | G8: Por pedido | H8: Baja | I8: No | J8: ISO 9001 / 14001 | K8: 30 | L8: 20485000 | M8: -0.0014 | N8: =INDEX(Parametros!$E$19:$E$28,MATCH(D8,Parametros!$B$19:$B$28,0))+INDEX(Parametros!$B$34:$B$36,MATCH(H8,Parametros!$A$34:$A$36,0))+INDEX(Parametros!$B$39:$B$40,MATCH(I8,Parametros!$A$39:$A$40,0))+INDEX(Parametros!$B$43:$B$46,MATCH(J8,Parametros!$A$43:$A$46,0))+INDEX(Parametros!$B$49:$B$52,MATCH(K8,Parametros!$A$49:$A$52,0))+M8 -> 0.0081
A9: PRV-008 | B9: Corporativo Insumos Unidos S.A.P.I. de C.V. | C9: Materias primas | D9: MP | E9: Veracruz | F9: 2013 | G9: Marco anual | H9: Alta | I9: No | J9: Ninguna | K9: 30 | L9: 32616000 | M9: 0.0043 | N9: =INDEX(Parametros!$E$19:$E$28,MATCH(D9,Parametros!$B$19:$B$28,0))+INDEX(Parametros!$B$34:$B$36,MATCH(H9,Parametros!$A$34:$A$36,0))+INDEX(Parametros!$B$39:$B$40,MATCH(I9,Parametros!$A$39:$A$40,0))+INDEX(Parametros!$B$43:$B$46,MATCH(J9,Parametros!$A$43:$A$46,0))+INDEX(Parametros!$B$49:$B$52,MATCH(K9,Parametros!$A$49:$A$52,0))+M9 -> 0.0363
A10: PRV-009 | B10: Proveedora Granos del Golfo S.A. de C.V. | C10: Materias primas | D10: MP | E10: Aguascalientes | F10: 2017 | G10: Marco anual | H10: Media | I10: No | J10: ISO 45001 | K10: 30 | L10: 27516000 | M10: -0.0073 | N10: =INDEX(Parametros!$E$19:$E$28,MATCH(D10,Parametros!$B$19:$B$28,0))+INDEX(Parametros!$B$34:$B$36,MATCH(H10,Parametros!$A$34:$A$36,0))+INDEX(Parametros!$B$39:$B$40,MATCH(I10,Parametros!$A$39:$A$40,0))+INDEX(Parametros!$B$43:$B$46,MATCH(J10,Parametros!$A$43:$A$46,0))+INDEX(Parametros!$B$49:$B$52,MATCH(K10,Parametros!$A$49:$A$52,0))+M10 -> 0.0097
A11: PRV-010 | B11: Operadora Fibras Integrales S. de R.L. de C.V. | C11: Materias primas | D11: MP | E11: Guanajuato | F11: 2021 | G11: Marco anual | H11: Baja | I11: No | J11: ISO 9001 | K11: 45 | L11: 20587000 | M11: -0.0039 | N11: =INDEX(Parametros!$E$19:$E$28,MATCH(D11,Parametros!$B$19:$B$28,0))+INDEX(Parametros!$B$34:$B$36,MATCH(H11,Parametros!$A$34:$A$36,0))+INDEX(Parametros!$B$39:$B$40,MATCH(I11,Parametros!$A$39:$A$40,0))+INDEX(Parametros!$B$43:$B$46,MATCH(J11,Parametros!$A$43:$A$46,0))+INDEX(Parametros!$B$49:$B$52,MATCH(K11,Parametros!$A$49:$A$52,0))+M11 -> 0.0106
A12: PRV-011 | B12: Comercializadora Empaques del Norte S.A.P.I. de C.V. | C12: Empaque y embalaje | D12: EE | E12: Aguascalientes | F12: 2019 | G12: Plurianual | H12: Alta | I12: No | J12: ISO 9001 / 14001 | K12: 45 | L12: 15071000 | M12: -0.0005 | N12: =INDEX(Parametros!$E$19:$E$28,MATCH(D12,Parametros!$B$19:$B$28,0))+INDEX(Parametros!$B$34:$B$36,MATCH(H12,Parametros!$A$34:$A$36,0))+INDEX(Parametros!$B$39:$B$40,MATCH(I12,Parametros!$A$39:$A$40,0))+INDEX(Parametros!$B$43:$B$46,MATCH(J12,Parametros!$A$43:$A$46,0))+INDEX(Parametros!$B$49:$B$52,MATCH(K12,Parametros!$A$49:$A$52,0))+M12 -> 0.0195
A13: PRV-012 | B13: Distribuidora Cartón de Occidente S.A. de C.V. | C13: Empaque y embalaje | D13: EE | E13: Guanajuato | F13: 2012 | G13: Plurianual | H13: Media | I13: No | J13: ISO 9001 | K13: 60 | L13: 12337000 | M13: 0.007 | N13: =INDEX(Parametros!$E$19:$E$28,MATCH(D13,Parametros!$B$19:$B$28,0))+INDEX(Parametros!$B$34:$B$36,MATCH(H13,Parametros!$A$34:$A$36,0))+INDEX(Parametros!$B$39:$B$40,MATCH(I13,Parametros!$A$39:$A$40,0))+INDEX(Parametros!$B$43:$B$46,MATCH(J13,Parametros!$A$43:$A$46,0))+INDEX(Parametros!$B$49:$B$52,MATCH(K13,Parametros!$A$49:$A$52,0))+M13 -> 0.027
... A101: PRV-100 | B101: Operadora Proyectos Integrales S. de R.L. de C.V. | C101: Servicios profesionales y consultoría | D101: SP | E101: Aguascalientes | F101: 2015 | G101: Plurianual | H101: Alta | I101: No | J101: ISO 9001 | K101: 30 | L101: 1754000 | M101: 0.0001 | N101: =INDEX(Parametros!$E$19:$E$28,MATCH(D101,Parametros!$B$19:$B$28,0))+INDEX(Parametros!$B$34:$B$36,MATCH(H101,Parametros!$A$34:$A$36,0))+INDEX(Parametros!$B$39:$B$40,MATCH(I101,Parametros!$A$39:$A$40,0))+INDEX(Parametros!$B$43:$B$46,MATCH(J101,Parametros!$A$43:$A$46,0))+INDEX(Parametros!$B$49:$B$52,MATCH(K101,Parametros!$A$49:$A$52,0))+M101 -> 0.0211

Sheet Contratos
A1: ID Proveedor | B1: Anio | C1: Monto Contrato Anual MXN | D1: Mes Renovacion | E1: Vigencia Meses | F1: Estatus | G1: Variacion vs Anio Anterior Pct
A2: PRV-001 | B2: 2023 | C2: 20306000 | D2: 7 | E2: 12 | F2: Cerrado | G2: =IF(B2="2023","",IFERROR(C2/SUMIFS(C:C,A:A,A2,B:B,TEXT(VALUE(B2)-1,"0"))-1,""))
A3: PRV-001 | B3: 2024 | C3: 18531000 | D3: 7 | E3: 12 | F3: Cerrado | G3: =IF(B3="2023","",IFERROR(C3/SUMIFS(C:C,A:A,A3,B:B,TEXT(VALUE(B3)-1,"0"))-1,"")) -> -0.087412587
A4: PRV-001 | B4: 2025 | C4: 19701000 | D4: 7 | E4: 12 | F4: Vigente | G4: =IF(B4="2023","",IFERROR(C4/SUMIFS(C:C,A:A,A4,B:B,TEXT(VALUE(B4)-1,"0"))-1,"")) -> 0.063137445
A5: PRV-002 | B5: 2023 | C5: 61167000 | D5: 2 | E5: 12 | F5: Cerrado | G5: =IF(B5="2023","",IFERROR(C5/SUMIFS(C:C,A:A,A5,B:B,TEXT(VALUE(B5)-1,"0"))-1,""))
A6: PRV-002 | B6: 2024 | C6: 57430000 | D6: 2 | E6: 12 | F6: Cerrado | G6: =IF(B6="2023","",IFERROR(C6/SUMIFS(C:C,A:A,A6,B:B,TEXT(VALUE(B6)-1,"0"))-1,"")) -> -0.061095035
A7: PRV-002 | B7: 2025 | C7: 59000000 | D7: 2 | E7: 12 | F7: Vigente | G7: =IF(B7="2023","",IFERROR(C7/SUMIFS(C:C,A:A,A7,B:B,TEXT(VALUE(B7)-1,"0"))-1,"")) -> 0.027337628
A8: PRV-003 | B8: 2023 | C8: 49976000 | D8: 3 | E8: 36 | F8: Cerrado | G8: =IF(B8="2023","",IFERROR(C8/SUMIFS(C:C,A:A,A8,B:B,TEXT(VALUE(B8)-1,"0"))-1,""))
A9: PRV-003 | B9: 2024 | C9: 47244000 | D9: 3 | E9: 36 | F9: Cerrado | G9: =IF(B9="2023","",IFERROR(C9/SUMIFS(C:C,A:A,A9,B:B,TEXT(VALUE(B9)-1,"0"))-1,"")) -> -0.05466624
A10: PRV-003 | B10: 2025 | C10: 52773000 | D10: 3 | E10: 36 | F10: Vigente | G10: =IF(B10="2023","",IFERROR(C10/SUMIFS(C:C,A:A,A10,B:B,TEXT(VALUE(B10)-1,"0"))-1,"")) -> 0.11703073
A11: PRV-004 | B11: 2023 | C11: 20298000 | D11: 3 | E11: 12 | F11: Cerrado | G11: =IF(B11="2023","",IFERROR(C11/SUMIFS(C:C,A:A,A11,B:B,TEXT(VALUE(B11)-1,"0"))-1,""))
A12: PRV-004 | B12: 2024 | C12: 22147000 | D12: 3 | E12: 12 | F12: Cerrado | G12: =IF(B12="2023","",IFERROR(C12/SUMIFS(C:C,A:A,A12,B:B,TEXT(VALUE(B12)-1,"0"))-1,"")) -> 0.091092718
A13: PRV-004 | B13: 2025 | C13: 21801000 | D13: 3 | E13: 12 | F13: Vigente | G13: =IF(B13="2023","",IFERROR(C13/SUMIFS(C:C,A:A,A13,B:B,TEXT(VALUE(B13)-1,"0"))-1,"")) -> -0.015622883
... A301: PRV-100 | B301: 2025 | C301: 2116000 | D301: 8 | E301: 36 | F301: Vigente | G301: =IF(B301="2023","",IFERROR(C301/SUMIFS(C:C,A:A,A301,B:B,TEXT(VALUE(B301)-1,"0"))-1,"")) -> 0.093540052

Sheet Historial Mensual
A1: ID Proveedor | B1: Periodo | C1: Anio | D1: Mes | E1: Monto Facturado MXN | F1: Indice Precio | G1: Aumento Precio Pct | H1: Calidad Servicio 0 100 | I1: Entregas Programadas | J1: Entregas Tardias | K1: OTIF Pct | L1: Tasa Rechazo Pct | M1: Problemas Logisticos | N1: Interrupciones | O1: Horas Interrupcion | P1: Cumplimiento Proceso 0 100 | Q1: Costo Incidencias MXN | R1: Costo No Calidad MXN | S1: Penalizaciones Cobradas MXN | T1: Costo Referencia Mercado MXN | U1: Costo Total Real MXN | V1: Rendimiento Neto Pct | W1: Indice Desempeno IDP | X1: Tasa Referencia Anual | Y1: Spread Riesgo Proveedor | Z1: Choque Tasa | AA1: Tasa Proveedor Anual | AB1: Tasa Proveedor Mensual | AC1: Rendimiento Exceso Pct
A2: PRV-001 | B2: 44927 | C2: 2023 | D2: 1 | E2: 1588975.4 | F2: 1 | G2: 0 | H2: 78.7 | I2: 7 | J2: 1 | K2: 0.8216 | L2: 0.0916 | M2: 1 | N2: 0 | O2: 0 | P2: 83.4 | Q2: 5895.71 | R2: 71748.85 | S2: 46847.9 | T2: 1626825.8 | U2: =E2+Q2+R2-S2 -> 1619772.1 | V2: =IF(T2=0,0,(T2-U2)/T2) -> 0.0043358852 | W2: =Parametros!$B$4*H2+Parametros!$B$5*K2*100+Parametros!$B$6*P2+Parametros!$B$7*(1-L2)*100 -> 82.499 | X2: =INDEX('Tasa Referencia'!$B$2:$B$37,MATCH(B2,'Tasa Referencia'!$A$2:$A$37,0)) -> 0.1125 | Y2: =INDEX('Catalogo Proveedores'!$N$2:$N$101,MATCH(A2,'Catalogo Proveedores'!$A$2:$A$101,0)) -> 0.0212 | Z2: 0.00021 | AA2: =X2+Y2+Z2 -> 0.13391 | AB2: =(1+AA2)^(1/12)-1 -> 0.010527683 | AC2: =V2-AB2 -> -0.006191798
A3: PRV-001 | B3: 44958 | C3: 2023 | D3: 2 | E3: 1492511.2 | F3: 1 | G3: 0 | H3: 76.9 | I3: 7 | J3: 1 | K3: 0.7917 | L3: 0.08 | M3: 0 | N3: 1 | O3: 24.5 | P3: 80.1 | Q3: 148774.03 | R3: 38773.18 | S3: 38786.25 | T3: 1503667.7 | U3: =E3+Q3+R3-S3 -> 1641272.2 | V3: =IF(T3=0,0,(T3-U3)/T3) -> -0.091512558 | W3: =Parametros!$B$4*H3+Parametros!$B$5*K3*100+Parametros!$B$6*P3+Parametros!$B$7*(1-L3)*100 -> 80.486 | X3: =INDEX('Tasa Referencia'!$B$2:$B$37,MATCH(B3,'Tasa Referencia'!$A$2:$A$37,0)) -> 0.1141 | Y3: =INDEX('Catalogo Proveedores'!$N$2:$N$101,MATCH(A3,'Catalogo Proveedores'!$A$2:$A$101,0)) -> 0.0212 | Z3: -4e-05 | AA3: =X3+Y3+Z3 -> 0.13526 | AB3: =(1+AA3)^(1/12)-1 -> 0.010627887 | AC3: =V3-AB3 -> -0.10214045
A4: PRV-001 | B4: 44986 | C4: 2023 | D4: 3 | E4: 1599057.1 | F4: 1 | G4: 0 | H4: 73.9 | I4: 7 | J4: 2 | K4: 0.735 | L4: 0.138 | M4: 5 | N4: 0 | O4: 0 | P4: 86.5 | Q4: 48096.09 | R4: 80035.66 | S4: 72587.73 | T4: 1577977.2 | U4: =E4+Q4+R4-S4 -> 1654601.2 | V4: =IF(T4=0,0,(T4-U4)/T4) -> -0.04855837 | W4: =Parametros!$B$4*H4+Parametros!$B$5*K4*100+Parametros!$B$6*P4+Parametros!$B$7*(1-L4)*100 -> 78.145 | X4: =INDEX('Tasa Referencia'!$B$2:$B$37,MATCH(B4,'Tasa Referencia'!$A$2:$A$37,0)) -> 0.114 | Y4: =INDEX('Catalogo Proveedores'!$N$2:$N$101,MATCH(A4,'Catalogo Proveedores'!$A$2:$A$101,0)) -> 0.0212 | Z4: -0.0005 | AA4: =X4+Y4+Z4 -> 0.1347 | AB4: =(1+AA4)^(1/12)-1 -> 0.010586334 | AC4: =V4-AB4 -> -0.059144705
A5: PRV-001 | B5: 45017 | C5: 2023 | D5: 4 | E5: 1834953.6 | F5: 1 | G5: 0 | H5: 74.5 | I5: 11 | J5: 1 | K5: 0.9138 | L5: 0.0511 | M5: 2 | N5: 0 | O5: 0 | P5: 79.4 | Q5: 26593.27 | R5: 46626.42 | S5: 31827.12 | T5: 1954335.4 | U5: =E5+Q5+R5-S5 -> 1876346.2 | V5: =IF(T5=0,0,(T5-U5)/T5) -> 0.039905735 | W5: =Parametros!$B$4*H5+Parametros!$B$5*K5*100+Parametros!$B$6*P5+Parametros!$B$7*(1-L5)*100 -> 83.6025 | X5: =INDEX('Tasa Referencia'!$B$2:$B$37,MATCH(B5,'Tasa Referencia'!$A$2:$A$37,0)) -> 0.1119 | Y5: =INDEX('Catalogo Proveedores'!$N$2:$N$101,MATCH(A5,'Catalogo Proveedores'!$A$2:$A$101,0)) -> 0.0212 | Z5: 0.00142 | AA5: =X5+Y5+Z5 -> 0.13452 | AB5: =(1+AA5)^(1/12)-1 -> 0.010572974 | AC5: =V5-AB5 -> 0.029332761
A6: PRV-001 | B6: 45047 | C6: 2023 | D6: 5 | E6: 1769464.3 | F6: 1 | G6: 0 | H6: 71.9 | I6: 11 | J6: 2 | K6: 0.8579 | L6: 0.1062 | M6: 0 | N6: 0 | O6: 0 | P6: 79.1 | Q6: 0 | R6: 113244.34 | S6: 63469.46 | T6: 1813582.6 | U6: =E6+Q6+R6-S6 -> 1819239.2 | V6: =IF(T6=0,0,(T6-U6)/T6) -> -0.0031190364 | W6: =Parametros!$B$4*H6+Parametros!$B$5*K6*100+Parametros!$B$6*P6+Parametros!$B$7*(1-L6)*100 -> 80.129 | X6: =INDEX('Tasa Referencia'!$B$2:$B$37,MATCH(B6,'Tasa Referencia'!$A$2:$A$37,0)) -> 0.1121 | Y6: =INDEX('Catalogo Proveedores'!$N$2:$N$101,MATCH(A6,'Catalogo Proveedores'!$A$2:$A$101,0)) -> 0.0212 | Z6: -0.00354 | AA6: =X6+Y6+Z6 -> 0.12976 | AB6: =(1+AA6)^(1/12)-1 -> 0.010218962 | AC6: =V6-AB6 -> -0.013337999
A7: PRV-001 | B7: 45078 | C7: 2023 | D7: 6 | E7: 1850306.3 | F7: 1 | G7: 0 | H7: 71.3 | I7: 11 | J7: 1 | K7: 0.8851 | L7: 0.0809 | M7: 3 | N7: 0 | O7: 0 | P7: 84.4 | Q7: 44079.15 | R7: 97206.15 | S7: 48614.77 | T7: 1937968.7 | U7: =E7+Q7+R7-S7 -> 1942976.8 | V7: =IF(T7=0,0,(T7-U7)/T7) -> -0.0025842213 | W7: =Parametros!$B$4*H7+Parametros!$B$5*K7*100+Parametros!$B$6*P7+Parametros!$B$7*(1-L7)*100 -> 82.1745 | X7: =INDEX('Tasa Referencia'!$B$2:$B$37,MATCH(B7,'Tasa Referencia'!$A$2:$A$37,0)) -> 0.1119 | Y7: =INDEX('Catalogo Proveedores'!$N$2:$N$101,MATCH(A7,'Catalogo Proveedores'!$A$2:$A$101,0)) -> 0.0212 | Z7: 0.00209 | AA7: =X7+Y7+Z7 -> 0.13519 | AB7: =(1+AA7)^(1/12)-1 -> 0.010622694 | AC7: =V7-AB7 -> -0.013206916
A8: PRV-001 | B8: 45108 | C8: 2023 | D8: 7 | E8: 1668144.7 | F8: 1.0126 | G8: 0.0126 | H8: 69.6 | I8: 9 | J8: 1 | K8: 0.9115 | L8: 0.0697 | M8: 1 | N8: 0 | O8: 0 | P8: 84 | Q8: 22830.65 | R8: 65080.29 | S8: 38235.61 | T8: 1742768.8 | U8: =E8+Q8+R8-S8 -> 1717820 | V8: =IF(T8=0,0,(T8-U8)/T8) -> 0.014315599 | W8: =Parametros!$B$4*H8+Parametros!$B$5*K8*100+Parametros!$B$6*P8+Parametros!$B$7*(1-L8)*100 -> 82.4595 | X8: =INDEX('Tasa Referencia'!$B$2:$B$37,MATCH(B8,'Tasa Referencia'!$A$2:$A$37,0)) -> 0.1132 | Y8: =INDEX('Catalogo Proveedores'!$N$2:$N$101,MATCH(A8,'Catalogo Proveedores'!$A$2:$A$101,0)) -> 0.0212 | Z8: 0.00011 | AA8: =X8+Y8+Z8 -> 0.13451 | AB8: =(1+AA8)^(1/12)-1 -> 0.010572232 | AC8: =V8-AB8 -> 0.0037433673
A9: PRV-001 | B9: 45139 | C9: 2023 | D9: 8 | E9: 1654819.3 | F9: 1.0126 | G9: 0 | H9: 70.1 | I9: 11 | J9: 1 | K9: 0.933 | L9: 0.0777 | M9: 0 | N9: 0 | O9: 0 | P9: 79.2 | Q9: 0 | R9: 75204.66 | S9: 41901.21 | T9: 1773243.5 | U9: =E9+Q9+R9-S9 -> 1688122.7 | V9: =IF(T9=0,0,(T9-U9)/T9) -> 0.048002861 | W9: =Parametros!$B$4*H9+Parametros!$B$5*K9*100+Parametros!$B$6*P9+Parametros!$B$7*(1-L9)*100 -> 82.1995 | X9: =INDEX('Tasa Referencia'!$B$2:$B$37,MATCH(B9,'Tasa Referencia'!$A$2:$A$37,0)) -> 0.1124 | Y9: =INDEX('Catalogo Proveedores'!$N$2:$N$101,MATCH(A9,'Catalogo Proveedores'!$A$2:$A$101,0)) -> 0.0212 | Z9: -0.00143 | AA9: =X9+Y9+Z9 -> 0.13217 | AB9: =(1+AA9)^(1/12)-1 -> 0.01039837 | AC9: =V9-AB9 -> 0.037604491
A10: PRV-001 | B10: 45170 | C10: 2023 | D10: 9 | E10: 1702140.4 | F10: 1.0126 | G10: 0 | H10: 69.8 | I10: 5 | J10: 0 | K10: 0.937 | L10: 0.1478 | M10: 0 | N10: 0 | O10: 0 | P10: 83 | Q10: 0 | R10: 106948.92 | S10: 75462.77 | T10: 1790541.1 | U10: =E10+Q10+R10-S10 -> 1733626.6 | V10: =IF(T10=0,0,(T10-U10)/T10) -> 0.031786251 | W10: =Parametros!$B$4*H10+Parametros!$B$5*K10*100+Parametros!$B$6*P10+Parametros!$B$7*(1-L10)*100 -> 81.923 | X10: =INDEX('Tasa Referencia'!$B$2:$B$37,MATCH(B10,'Tasa Referencia'!$A$2:$A$37,0)) -> 0.1134 | Y10: =INDEX('Catalogo Proveedores'!$N$2:$N$101,MATCH(A10,'Catalogo Proveedores'!$A$2:$A$101,0)) -> 0.0212 | Z10: -0.00347 | AA10: =X10+Y10+Z10 -> 0.13113 | AB10: =(1+AA10)^(1/12)-1 -> 0.010320992 | AC10: =V10-AB10 -> 0.021465259
A11: PRV-001 | B11: 45200 | C11: 2023 | D11: 10 | E11: 1659190.9 | F11: 1.0126 | G11: 0 | H11: 68 | I11: 10 | J11: 1 | K11: 0.933 | L11: 0.1285 | M11: 1 | N11: 0 | O11: 0 | P11: 79.7 | Q11: 12274.66 | R11: 103427.44 | S11: 67261.51 | T11: 1790197.2 | U11: =E11+Q11+R11-S11 -> 1707631.5 | V11: =IF(T11=0,0,(T11-U11)/T11) -> 0.046121003 | W11: =Parametros!$B$4*H11+Parametros!$B$5*K11*100+Parametros!$B$6*P11+Parametros!$B$7*(1-L11)*100 -> 80.8025 | X11: =INDEX('Tasa Referencia'!$B$2:$B$37,MATCH(B11,'Tasa Referencia'!$A$2:$A$37,0)) -> 0.1103 | Y11: =INDEX('Catalogo Proveedores'!$N$2:$N$101,MATCH(A11,'Catalogo Proveedores'!$A$2:$A$101,0)) -> 0.0212 | Z11: 0.00025 | AA11: =X11+Y11+Z11 -> 0.13175 | AB11: =(1+AA11)^(1/12)-1 -> 0.010367129 | AC11: =V11-AB11 -> 0.035753874
A12: PRV-001 | B12: 45231 | C12: 2023 | D12: 11 | E12: 1573092.3 | F12: 1.0126 | G12: 0 | H12: 69.7 | I12: 13 | J12: 2 | K12: 0.8824 | L12: 0.0821 | M12: 0 | N12: 0 | O12: 0 | P12: 84.9 | Q12: 0 | R12: 46603.28 | S12: 45014.98 | T12: 1740512.2 | U12: =E12+Q12+R12-S12 -> 1574680.6 | V12: =IF(T12=0,0,(T12-U12)/T12) -> 0.095277467 | W12: =Parametros!$B$4*H12+Parametros!$B$5*K12*100+Parametros!$B$6*P12+Parametros!$B$7*(1-L12)*100 -> 81.6155 | X12: =INDEX('Tasa Referencia'!$B$2:$B$37,MATCH(B12,'Tasa Referencia'!$A$2:$A$37,0)) -> 0.1144 | Y12: =INDEX('Catalogo Proveedores'!$N$2:$N$101,MATCH(A12,'Catalogo Proveedores'!$A$2:$A$101,0)) -> 0.0212 | Z12: 0.00183 | AA12: =X12+Y12+Z12 -> 0.13743 | AB12: =(1+AA12)^(1/12)-1 -> 0.010788727 | AC12: =V12-AB12 -> 0.08448874
A13: PRV-001 | B13: 45261 | C13: 2023 | D13: 12 | E13: 1483367.7 | F13: 1.0126 | G13: 0 | H13: 73.6 | I13: 7 | J13: 1 | K13: 0.9127 | L13: 0.1111 | M13: 1 | N13: 0 | O13: 0 | P13: 85.6 | Q13: 4794.98 | R13: 82864.88 | S13: 52406.96 | T13: 1559088 | U13: =E13+Q13+R13-S13 -> 1518620.6 | V13: =IF(T13=0,0,(T13-U13)/T13) -> 0.025955834 | W13: =Parametros!$B$4*H13+Parametros!$B$5*K13*100+Parametros!$B$6*P13+Parametros!$B$7*(1-L13)*100 -> 83.5945 | X13: =INDEX('Tasa Referencia'!$B$2:$B$37,MATCH(B13,'Tasa Referencia'!$A$2:$A$37,0)) -> 0.1124 | Y13: =INDEX('Catalogo Proveedores'!$N$2:$N$101,MATCH(A13,'Catalogo Proveedores'!$A$2:$A$101,0)) -> 0.0212 | Z13: 0.00421 | AA13: =X13+Y13+Z13 -> 0.13781 | AB13: =(1+AA13)^(1/12)-1 -> 0.010816864 | AC13: =V13-AB13 -> 0.01513897
... A3601: PRV-100 | B3601: 45992 | C3601: 2025 | D3601: 12 | E3601: 147539.43 | F3601: 1.2239 | G3601: 0 | H3601: 85.3 | I3601: 4 | J3601: 0 | K3601: 0.9168 | L3601: 0.0732 | M3601: 0 | N3601: 0 | O3601: 0 | P3601: 78 | Q3601: 0 | R3601: 4731.14 | S3601: 3239.9 | T3601: 157183.57 | U3601: =E3601+Q3601+R3601-S3601 -> 149030.67 | V3601: =IF(T3601=0,0,(T3601-U3601)/T3601) -> 0.051868653 | W3601: =Parametros!$B$4*H3601+Parametros!$B$5*K3601*100+Parametros!$B$6*P3601+Parametros!$B$7*(1-L3601)*100 -> 86.861 | X3601: =INDEX('Tasa Referencia'!$B$2:$B$37,MATCH(B3601,'Tasa Referencia'!$A$2:$A$37,0)) -> 0.0696 | Y3601: =INDEX('Catalogo Proveedores'!$N$2:$N$101,MATCH(A3601,'Catalogo Proveedores'!$A$2:$A$101,0)) -> 0.0211 | Z3601: -0.00094 | AA3601: =X3601+Y3601+Z3601 -> 0.08976 | AB3601: =(1+AA3601)^(1/12)-1 -> 0.0071888406 | AC3601: =V3601-AB3601 -> 0.044679812

Sheet Eventos Incidencias
A1: ID Evento | B1: ID Proveedor | C1: Fecha | D1: Categoria | E1: Tipo | F1: Severidad | G1: Dias Retraso | H1: Horas Interrupcion | I1: Costo Impacto MXN | J1: Estatus Resolucion
A2: EV-00001 | B2: PRV-001 | C2: 44940 | D2: Problema logístico | E2: Entrega incompleta | F2: Baja | G2: 1 | H2: 0 | I2: 5895.71 | J2: Resuelto
A3: EV-00002 | B3: PRV-001 | C3: 44961 | D3: Interrupción | E3: Falla de sistemas | F3: Alta | G3: 2 | H3: 24.5 | I3: 148774.03 | J3: Resuelto
A4: EV-00003 | B4: PRV-001 | C4: 44988 | D4: Problema logístico | E4: Entrega incompleta | F4: Media | G4: 1 | H4: 0 | I4: 18319.72 | J4: En seguimiento
A5: EV-00004 | B5: PRV-001 | C5: 45011 | D5: Problema logístico | E5: Error de documentación | F5: Baja | G5: 1 | H5: 0 | I5: 5979.78 | J5: Resuelto
A6: EV-00005 | B6: PRV-001 | C6: 45004 | D6: Problema logístico | E6: Cambio de ruta / transporte | F6: Media | G6: 2 | H6: 0 | I6: 15019.47 | J6: Resuelto
A7: EV-00006 | B7: PRV-001 | C7: 45003 | D7: Problema logístico | E7: Falta de inventario | F7: Baja | G7: 1 | H7: 0 | I7: 2624.87 | J7: Resuelto
A8: EV-00007 | B8: PRV-001 | C8: 44998 | D8: Problema logístico | E8: Cambio de ruta / transporte | F8: Baja | G8: 1 | H8: 0 | I8: 6152.25 | J8: En seguimiento
A9: EV-00008 | B9: PRV-001 | C9: 45041 | D9: Problema logístico | E9: Retraso de entrega | F9: Baja | G9: 0 | H9: 0 | I9: 2898.12 | J9: Resuelto
A10: EV-00009 | B10: PRV-001 | C10: 45036 | D10: Problema logístico | E10: Entrega incompleta | F10: Media | G10: 1 | H10: 0 | I10: 23695.15 | J10: Resuelto
A11: EV-00010 | B11: PRV-001 | C11: 45098 | D11: Problema logístico | E11: Falta de inventario | F11: Baja | G11: 0 | H11: 0 | I11: 6029.9 | J11: Resuelto
A12: EV-00011 | B12: PRV-001 | C12: 45099 | D12: Problema logístico | E12: Daño en tránsito | F12: Baja | G12: 1 | H12: 0 | I12: 6329.89 | J12: Resuelto
A13: EV-00012 | B13: PRV-001 | C13: 45080 | D13: Problema logístico | E13: Error de documentación | F13: Media | G13: 5 | H13: 0 | I13: 31719.37 | J13: En seguimiento
... A4297: EV-04296 | B4297: PRV-100 | C4297: 45906 | D4297: Interrupción | E4297: Restricción regulatoria | F4297: Baja | G4297: 1 | H4297: 3.6 | I4297: 2215.94 | J4297: En seguimiento

Sheet Auditoria Cumplimiento
A1: ID Proveedor | B1: Anio | C1: Documentacion Fiscal | D1: Cumplimiento Contractual | E1: Facturacion Correcta | F1: Seguridad Higiene Ambiental | G1: Confidencialidad Etica | H1: Certificaciones Vigentes | I1: No Conformidades Auditoria | J1: Cumplimiento del Proceso
A2: PRV-001 | B2: 2023 | C2: 72.3 | D2: 72.7 | E2: 70.4 | F2: 83.2 | G2: 73.4 | H2: 85 | I2: 4 | J2: =AVERAGE(C2:H2) -> 76.166667
A3: PRV-001 | B3: 2024 | C3: 73.1 | D3: 66 | E3: 77.5 | F3: 83.4 | G3: 72.9 | H3: 84.6 | I3: 1 | J3: =AVERAGE(C3:H3) -> 76.25
A4: PRV-001 | B4: 2025 | C4: 82.2 | D4: 80.1 | E4: 81.5 | F4: 73 | G4: 87 | H4: 82.7 | I4: 1 | J4: =AVERAGE(C4:H4) -> 81.083333
A5: PRV-002 | B5: 2023 | C5: 86.3 | D5: 87.4 | E5: 93.4 | F5: 85 | G5: 75.4 | H5: 74.4 | I5: 3 | J5: =AVERAGE(C5:H5) -> 83.65
A6: PRV-002 | B6: 2024 | C6: 86.1 | D6: 78.4 | E6: 86.3 | F6: 69.9 | G6: 81.8 | H6: 75.3 | I6: 2 | J6: =AVERAGE(C6:H6) -> 79.633333
A7: PRV-002 | B7: 2025 | C7: 84.3 | D7: 72.9 | E7: 76.9 | F7: 82.1 | G7: 85.7 | H7: 84.9 | I7: 3 | J7: =AVERAGE(C7:H7) -> 81.133333
A8: PRV-003 | B8: 2023 | C8: 74.2 | D8: 83.5 | E8: 86.8 | F8: 82.3 | G8: 81.6 | H8: 70.3 | I8: 0 | J8: =AVERAGE(C8:H8) -> 79.783333
A9: PRV-003 | B9: 2024 | C9: 79.3 | D9: 71.6 | E9: 75.6 | F9: 73.6 | G9: 85 | H9: 71.4 | I9: 2 | J9: =AVERAGE(C9:H9) -> 76.083333
A10: PRV-003 | B10: 2025 | C10: 77.3 | D10: 72.2 | E10: 79.1 | F10: 89.4 | G10: 80.4 | H10: 83.9 | I10: 2 | J10: =AVERAGE(C10:H10) -> 80.383333
A11: PRV-004 | B11: 2023 | C11: 73.1 | D11: 74.3 | E11: 78 | F11: 76.3 | G11: 82.2 | H11: 72.7 | I11: 6 | J11: =AVERAGE(C11:H11) -> 76.1
A12: PRV-004 | B12: 2024 | C12: 66.3 | D12: 72.8 | E12: 75.1 | F12: 84.6 | G12: 86 | H12: 69.6 | I12: 3 | J12: =AVERAGE(C12:H12) -> 75.733333
A13: PRV-004 | B13: 2025 | C13: 79 | D13: 77 | E13: 70.5 | F13: 76 | G13: 78.1 | H13: 68.6 | I13: 3 | J13: =AVERAGE(C13:H13) -> 74.866667
... A301: PRV-100 | B301: 2025 | C301: 64 | D301: 67.3 | E301: 74.9 | F301: 70.5 | G301: 71.3 | H301: 82.1 | I301: 1 | J301: =AVERAGE(C301:H301) -> 71.683333

Sheet Resumen Anual
A1: ID Proveedor | B1: Razon Social | C1: Giro | D1: Año | E1: Monto Contrato Anual MXN | F1: Monto Facturado MXN | G1: Aumento Precio Acum Pct | H1: Calidad Prom | I1: OTIF Prom | J1: Tasa Rechazo Prom | K1: Problemas Logisticos | L1: Interrupciones | M1: Horas Interrupcion | N1: Cumplimiento Proceso Prom | O1: Costo Incidencias MXN | P1: Penalizaciones MXN | Q1: Rendimiento Prom Mensual | R1: Volatilidad Mensual | S1: IDP Prom | T1: Calificacion Auditoria | U1: Tasa Proveedor Anual Prom | V1: Rendimiento Exceso Prom
A2: PRV-001 | B2: =INDEX('Catalogo Proveedores'!$B$2:$B$101,MATCH(A2,'Catalogo Proveedores'!$A$2:$A$101,0)) -> Comercializadora Aceros del Norte S. de R.L. de C.V. | C2: =INDEX('Catalogo Proveedores'!$C$2:$C$101,MATCH(A2,'Catalogo Proveedores'!$A$2:$A$101,0)) -> Materias primas | D2: 2023 | E2: =SUMIFS(Contratos!$C:$C,Contratos!$A:$A,A2,Contratos!$B:$B,D2) -> 20306000 | F2: =SUMIFS('Historial Mensual'!$E$2:$E$3601,'Historial Mensual'!$A$2:$A$3601,$A2,'Historial Mensual'!$C$2:$C$3601,$D2) -> 19876023 | G2: =SUMPRODUCT(('Historial Mensual'!$A$2:$A$3601=A2)*('Historial Mensual'!$C$2:$C$3601=D2)*'Historial Mensual'!$G$2:$G$3601) -> 0.0126 | H2: =AVERAGEIFS('Historial Mensual'!$H$2:$H$3601,'Historial Mensual'!$A$2:$A$3601,$A2,'Historial Mensual'!$C$2:$C$3601,$D2) -> 72.333333 | I2: =AVERAGEIFS('Historial Mensual'!$K$2:$K$3601,'Historial Mensual'!$A$2:$A$3601,$A2,'Historial Mensual'!$C$2:$C$3601,$D2) -> 0.876225 | J2: =AVERAGEIFS('Historial Mensual'!$L$2:$L$3601,'Historial Mensual'!$A$2:$A$3601,$A2,'Historial Mensual'!$C$2:$C$3601,$D2) -> 0.097058333 | K2: =SUMIFS('Historial Mensual'!$M$2:$M$3601,'Historial Mensual'!$A$2:$A$3601,$A2,'Historial Mensual'!$C$2:$C$3601,$D2) -> 14 | L2: =SUMIFS('Historial Mensual'!$N$2:$N$3601,'Historial Mensual'!$A$2:$A$3601,$A2,'Historial Mensual'!$C$2:$C$3601,$D2) -> 1 | M2: =SUMIFS('Historial Mensual'!$O$2:$O$3601,'Historial Mensual'!$A$2:$A$3601,$A2,'Historial Mensual'!$C$2:$C$3601,$D2) -> 24.5 | N2: =AVERAGEIFS('Historial Mensual'!$P$2:$P$3601,'Historial Mensual'!$A$2:$A$3601,$A2,'Historial Mensual'!$C$2:$C$3601,$D2) -> 82.441667 | O2: =SUMIFS('Historial Mensual'!$Q$2:$Q$3601,'Historial Mensual'!$A$2:$A$3601,$A2,'Historial Mensual'!$C$2:$C$3601,$D2) -> 313338.54 | P2: =SUMIFS('Historial Mensual'!$S$2:$S$3601,'Historial Mensual'!$A$2:$A$3601,$A2,'Historial Mensual'!$C$2:$C$3601,$D2) -> 622416.27 | Q2: =AVERAGEIFS('Historial Mensual'!$V$2:$V$3601,'Historial Mensual'!$A$2:$A$3601,$A2,'Historial Mensual'!$C$2:$C$3601,$D2) -> 0.013327204 | R2: =SQRT(SUMPRODUCT(('Historial Mensual'!$A$2:$A$3601=A2)*('Historial Mensual'!$C$2:$C$3601=D2)*('Historial Mensual'!$V$2:$V$3601-Q2)^2)/11) -> 0.048267239 | S2: =AVERAGEIFS('Historial Mensual'!$W$2:$W$3601,'Historial Mensual'!$A$2:$A$3601,$A2,'Historial Mensual'!$C$2:$C$3601,$D2) -> 81.635875 | T2: =SUMIFS('Auditoria Cumplimiento'!$J:$J,'Auditoria Cumplimiento'!$A:$A,A2,'Auditoria Cumplimiento'!$B:$B,D2) -> 76.166667 | U2: =AVERAGEIFS('Historial Mensual'!$AA$2:$AA$3601,'Historial Mensual'!$A$2:$A$3601,$A2,'Historial Mensual'!$C$2:$C$3601,$D2) -> 0.13401167 | V2: =AVERAGEIFS('Historial Mensual'!$AC$2:$AC$3601,'Historial Mensual'!$A$2:$A$3601,$A2,'Historial Mensual'!$C$2:$C$3601,$D2) -> 0.0027921332
A3: PRV-001 | B3: =INDEX('Catalogo Proveedores'!$B$2:$B$101,MATCH(A3,'Catalogo Proveedores'!$A$2:$A$101,0)) -> Comercializadora Aceros del Norte S. de R.L. de C.V. | C3: =INDEX('Catalogo Proveedores'!$C$2:$C$101,MATCH(A3,'Catalogo Proveedores'!$A$2:$A$101,0)) -> Materias primas | D3: 2024 | E3: =SUMIFS(Contratos!$C:$C,Contratos!$A:$A,A3,Contratos!$B:$B,D3) -> 18531000 | F3: =SUMIFS('Historial Mensual'!$E$2:$E$3601,'Historial Mensual'!$A$2:$A$3601,$A3,'Historial Mensual'!$C$2:$C$3601,$D3) -> 18575310 | G3: =SUMPRODUCT(('Historial Mensual'!$A$2:$A$3601=A3)*('Historial Mensual'!$C$2:$C$3601=D3)*'Historial Mensual'!$G$2:$G$3601) -> 0.051 | H3: =AVERAGEIFS('Historial Mensual'!$H$2:$H$3601,'Historial Mensual'!$A$2:$A$3601,$A3,'Historial Mensual'!$C$2:$C$3601,$D3) -> 76.041667 | I3: =AVERAGEIFS('Historial Mensual'!$K$2:$K$3601,'Historial Mensual'!$A$2:$A$3601,$A3,'Historial Mensual'!$C$2:$C$3601,$D3) -> 0.90094167 | J3: =AVERAGEIFS('Historial Mensual'!$L$2:$L$3601,'Historial Mensual'!$A$2:$A$3601,$A3,'Historial Mensual'!$C$2:$C$3601,$D3) -> 0.099891667 | K3: =SUMIFS('Historial Mensual'!$M$2:$M$3601,'Historial Mensual'!$A$2:$A$3601,$A3,'Historial Mensual'!$C$2:$C$3601,$D3) -> 10 | L3: =SUMIFS('Historial Mensual'!$N$2:$N$3601,'Historial Mensual'!$A$2:$A$3601,$A3,'Historial Mensual'!$C$2:$C$3601,$D3) -> 2 | M3: =SUMIFS('Historial Mensual'!$O$2:$O$3601,'Historial Mensual'!$A$2:$A$3601,$A3,'Historial Mensual'!$C$2:$C$3601,$D3) -> 24.2 | N3: =AVERAGEIFS('Historial Mensual'!$P$2:$P$3601,'Historial Mensual'!$A$2:$A$3601,$A3,'Historial Mensual'!$C$2:$C$3601,$D3) -> 82.341667 | O3: =SUMIFS('Historial Mensual'!$Q$2:$Q$3601,'Historial Mensual'!$A$2:$A$3601,$A3,'Historial Mensual'!$C$2:$C$3601,$D3) -> 357146.18 | P3: =SUMIFS('Historial Mensual'!$S$2:$S$3601,'Historial Mensual'!$A$2:$A$3601,$A3,'Historial Mensual'!$C$2:$C$3601,$D3) -> 578642.6 | Q3: =AVERAGEIFS('Historial Mensual'!$V$2:$V$3601,'Historial Mensual'!$A$2:$A$3601,$A3,'Historial Mensual'!$C$2:$C$3601,$D3) -> 0.03979177 | R3: =SQRT(SUMPRODUCT(('Historial Mensual'!$A$2:$A$3601=A3)*('Historial Mensual'!$C$2:$C$3601=D3)*('Historial Mensual'!$V$2:$V$3601-Q3)^2)/11) -> 0.042243186 | S3: =AVERAGEIFS('Historial Mensual'!$W$2:$W$3601,'Historial Mensual'!$A$2:$A$3601,$A3,'Historial Mensual'!$C$2:$C$3601,$D3) -> 83.612792 | T3: =SUMIFS('Auditoria Cumplimiento'!$J:$J,'Auditoria Cumplimiento'!$A:$A,A3,'Auditoria Cumplimiento'!$B:$B,D3) -> 76.25 | U3: =AVERAGEIFS('Historial Mensual'!$AA$2:$AA$3601,'Historial Mensual'!$A$2:$A$3601,$A3,'Historial Mensual'!$C$2:$C$3601,$D3) -> 0.12663167 | V3: =AVERAGEIFS('Historial Mensual'!$AC$2:$AC$3601,'Historial Mensual'!$A$2:$A$3601,$A3,'Historial Mensual'!$C$2:$C$3601,$D3) -> 0.029808128
A4: PRV-001 | B4: =INDEX('Catalogo Proveedores'!$B$2:$B$101,MATCH(A4,'Catalogo Proveedores'!$A$2:$A$101,0)) -> Comercializadora Aceros del Norte S. de R.L. de C.V. | C4: =INDEX('Catalogo Proveedores'!$C$2:$C$101,MATCH(A4,'Catalogo Proveedores'!$A$2:$A$101,0)) -> Materias primas | D4: 2025 | E4: =SUMIFS(Contratos!$C:$C,Contratos!$A:$A,A4,Contratos!$B:$B,D4) -> 19701000 | F4: =SUMIFS('Historial Mensual'!$E$2:$E$3601,'Historial Mensual'!$A$2:$A$3601,$A4,'Historial Mensual'!$C$2:$C$3601,$D4) -> 19728095 | G4: =SUMPRODUCT(('Historial Mensual'!$A$2:$A$3601=A4)*('Historial Mensual'!$C$2:$C$3601=D4)*'Historial Mensual'!$G$2:$G$3601) -> 0.115 | H4: =AVERAGEIFS('Historial Mensual'!$H$2:$H$3601,'Historial Mensual'!$A$2:$A$3601,$A4,'Historial Mensual'!$C$2:$C$3601,$D4) -> 74.075 | I4: =AVERAGEIFS('Historial Mensual'!$K$2:$K$3601,'Historial Mensual'!$A$2:$A$3601,$A4,'Historial Mensual'!$C$2:$C$3601,$D4) -> 0.85749167 | J4: =AVERAGEIFS('Historial Mensual'!$L$2:$L$3601,'Historial Mensual'!$A$2:$A$3601,$A4,'Historial Mensual'!$C$2:$C$3601,$D4) -> 0.1078 | K4: =SUMIFS('Historial Mensual'!$M$2:$M$3601,'Historial Mensual'!$A$2:$A$3601,$A4,'Historial Mensual'!$C$2:$C$3601,$D4) -> 18 | L4: =SUMIFS('Historial Mensual'!$N$2:$N$3601,'Historial Mensual'!$A$2:$A$3601,$A4,'Historial Mensual'!$C$2:$C$3601,$D4) -> 3 | M4: =SUMIFS('Historial Mensual'!$O$2:$O$3601,'Historial Mensual'!$A$2:$A$3601,$A4,'Historial Mensual'!$C$2:$C$3601,$D4) -> 93.4 | N4: =AVERAGEIFS('Historial Mensual'!$P$2:$P$3601,'Historial Mensual'!$A$2:$A$3601,$A4,'Historial Mensual'!$C$2:$C$3601,$D4) -> 79.65 | O4: =SUMIFS('Historial Mensual'!$Q$2:$Q$3601,'Historial Mensual'!$A$2:$A$3601,$A4,'Historial Mensual'!$C$2:$C$3601,$D4) -> 881409.53 | P4: =SUMIFS('Historial Mensual'!$S$2:$S$3601,'Historial Mensual'!$A$2:$A$3601,$A4,'Historial Mensual'!$C$2:$C$3601,$D4) -> 682605.21 | Q4: =AVERAGEIFS('Historial Mensual'!$V$2:$V$3601,'Historial Mensual'!$A$2:$A$3601,$A4,'Historial Mensual'!$C$2:$C$3601,$D4) -> -0.034772145 | R4: =SQRT(SUMPRODUCT(('Historial Mensual'!$A$2:$A$3601=A4)*('Historial Mensual'!$C$2:$C$3601=D4)*('Historial Mensual'!$V$2:$V$3601-Q4)^2)/11) -> 0.096370767 | S4: =AVERAGEIFS('Historial Mensual'!$W$2:$W$3601,'Historial Mensual'!$A$2:$A$3601,$A4,'Historial Mensual'!$C$2:$C$3601,$D4) -> 80.964 | T4: =SUMIFS('Auditoria Cumplimiento'!$J:$J,'Auditoria Cumplimiento'!$A:$A,A4,'Auditoria Cumplimiento'!$B:$B,D4) -> 81.083333 | U4: =AVERAGEIFS('Historial Mensual'!$AA$2:$AA$3601,'Historial Mensual'!$A$2:$A$3601,$A4,'Historial Mensual'!$C$2:$C$3601,$D4) -> 0.10280583 | V4: =AVERAGEIFS('Historial Mensual'!$AC$2:$AC$3601,'Historial Mensual'!$A$2:$A$3601,$A4,'Historial Mensual'!$C$2:$C$3601,$D4) -> -0.042959522
A5: PRV-002 | B5: =INDEX('Catalogo Proveedores'!$B$2:$B$101,MATCH(A5,'Catalogo Proveedores'!$A$2:$A$101,0)) -> Distribuidora Resinas de Occidente S.A.P.I. de C.V. | C5: =INDEX('Catalogo Proveedores'!$C$2:$C$101,MATCH(A5,'Catalogo Proveedores'!$A$2:$A$101,0)) -> Materias primas | D5: 2023 | E5: =SUMIFS(Contratos!$C:$C,Contratos!$A:$A,A5,Contratos!$B:$B,D5) -> 61167000 | F5: =SUMIFS('Historial Mensual'!$E$2:$E$3601,'Historial Mensual'!$A$2:$A$3601,$A5,'Historial Mensual'!$C$2:$C$3601,$D5) -> 61441884 | G5: =SUMPRODUCT(('Historial Mensual'!$A$2:$A$3601=A5)*('Historial Mensual'!$C$2:$C$3601=D5)*'Historial Mensual'!$G$2:$G$3601) -> 0.0286 | H5: =AVERAGEIFS('Historial Mensual'!$H$2:$H$3601,'Historial Mensual'!$A$2:$A$3601,$A5,'Historial Mensual'!$C$2:$C$3601,$D5) -> 72.891667 | I5: =AVERAGEIFS('Historial Mensual'!$K$2:$K$3601,'Historial Mensual'!$A$2:$A$3601,$A5,'Historial Mensual'!$C$2:$C$3601,$D5) -> 0.79094167 | J5: =AVERAGEIFS('Historial Mensual'!$L$2:$L$3601,'Historial Mensual'!$A$2:$A$3601,$A5,'Historial Mensual'!$C$2:$C$3601,$D5) -> 0.10819167 | K5: =SUMIFS('Historial Mensual'!$M$2:$M$3601,'Historial Mensual'!$A$2:$A$3601,$A5,'Historial Mensual'!$C$2:$C$3601,$D5) -> 16 | L5: =SUMIFS('Historial Mensual'!$N$2:$N$3601,'Historial Mensual'!$A$2:$A$3601,$A5,'Historial Mensual'!$C$2:$C$3601,$D5) -> 3 | M5: =SUMIFS('Historial Mensual'!$O$2:$O$3601,'Historial Mensual'!$A$2:$A$3601,$A5,'Historial Mensual'!$C$2:$C$3601,$D5) -> 118.6 | N5: =AVERAGEIFS('Historial Mensual'!$P$2:$P$3601,'Historial Mensual'!$A$2:$A$3601,$A5,'Historial Mensual'!$C$2:$C$3601,$D5) -> 83.808333 | O5: =SUMIFS('Historial Mensual'!$Q$2:$Q$3601,'Historial Mensual'!$A$2:$A$3601,$A5,'Historial Mensual'!$C$2:$C$3601,$D5) -> 2913589.5 | P5: =SUMIFS('Historial Mensual'!$S$2:$S$3601,'Historial Mensual'!$A$2:$A$3601,$A5,'Historial Mensual'!$C$2:$C$3601,$D5) -> 2502740.7 | Q5: =AVERAGEIFS('Historial Mensual'!$V$2:$V$3601,'Historial Mensual'!$A$2:$A$3601,$A5,'Historial Mensual'!$C$2:$C$3601,$D5) -> -0.019640046 | R5: =SQRT(SUMPRODUCT(('Historial Mensual'!$A$2:$A$3601=A5)*('Historial Mensual'!$C$2:$C$3601=D5)*('Historial Mensual'!$V$2:$V$3601-Q5)^2)/11) -> 0.080768958 | S5: =AVERAGEIFS('Historial Mensual'!$W$2:$W$3601,'Historial Mensual'!$A$2:$A$3601,$A5,'Historial Mensual'!$C$2:$C$3601,$D5) -> 79.379125 | T5: =SUMIFS('Auditoria Cumplimiento'!$J:$J,'Auditoria Cumplimiento'!$A:$A,A5,'Auditoria Cumplimiento'!$B:$B,D5) -> 83.65 | U5: =AVERAGEIFS('Historial Mensual'!$AA$2:$AA$3601,'Historial Mensual'!$A$2:$A$3601,$A5,'Historial Mensual'!$C$2:$C$3601,$D5) -> 0.12469333 | V5: =AVERAGEIFS('Historial Mensual'!$AC$2:$AC$3601,'Historial Mensual'!$A$2:$A$3601,$A5,'Historial Mensual'!$C$2:$C$3601,$D5) -> -0.029480525
A6: PRV-002 | B6: =INDEX('Catalogo Proveedores'!$B$2:$B$101,MATCH(A6,'Catalogo Proveedores'!$A$2:$A$101,0)) -> Distribuidora Resinas de Occidente S.A.P.I. de C.V. | C6: =INDEX('Catalogo Proveedores'!$C$2:$C$101,MATCH(A6,'Catalogo Proveedores'!$A$2:$A$101,0)) -> Materias primas | D6: 2024 | E6: =SUMIFS(Contratos!$C:$C,Contratos!$A:$A,A6,Contratos!$B:$B,D6) -> 57430000 | F6: =SUMIFS('Historial Mensual'!$E$2:$E$3601,'Historial Mensual'!$A$2:$A$3601,$A6,'Historial Mensual'!$C$2:$C$3601,$D6) -> 58272135 | G6: =SUMPRODUCT(('Historial Mensual'!$A$2:$A$3601=A6)*('Historial Mensual'!$C$2:$C$3601=D6)*'Historial Mensual'!$G$2:$G$3601) -> 0.0722 | H6: =AVERAGEIFS('Historial Mensual'!$H$2:$H$3601,'Historial Mensual'!$A$2:$A$3601,$A6,'Historial Mensual'!$C$2:$C$3601,$D6) -> 72.766667 | I6: =AVERAGEIFS('Historial Mensual'!$K$2:$K$3601,'Historial Mensual'!$A$2:$A$3601,$A6,'Historial Mensual'!$C$2:$C$3601,$D6) -> 0.801625 | J6: =AVERAGEIFS('Historial Mensual'!$L$2:$L$3601,'Historial Mensual'!$A$2:$A$3601,$A6,'Historial Mensual'!$C$2:$C$3601,$D6) -> 0.10200833 | K6: =SUMIFS('Historial Mensual'!$M$2:$M$3601,'Historial Mensual'!$A$2:$A$3601,$A6,'Historial Mensual'!$C$2:$C$3601,$D6) -> 13 | L6: =SUMIFS('Historial Mensual'!$N$2:$N$3601,'Historial Mensual'!$A$2:$A$3601,$A6,'Historial Mensual'!$C$2:$C$3601,$D6) -> 3 | M6: =SUMIFS('Historial Mensual'!$O$2:$O$3601,'Historial Mensual'!$A$2:$A$3601,$A6,'Historial Mensual'!$C$2:$C$3601,$D6) -> 13.3 | N6: =AVERAGEIFS('Historial Mensual'!$P$2:$P$3601,'Historial Mensual'!$A$2:$A$3601,$A6,'Historial Mensual'!$C$2:$C$3601,$D6) -> 82.208333 | O6: =SUMIFS('Historial Mensual'!$Q$2:$Q$3601,'Historial Mensual'!$A$2:$A$3601,$A6,'Historial Mensual'!$C$2:$C$3601,$D6) -> 1299816.3 | P6: =SUMIFS('Historial Mensual'!$S$2:$S$3601,'Historial Mensual'!$A$2:$A$3601,$A6,'Historial Mensual'!$C$2:$C$3601,$D6) -> 2281928.7 | Q6: =AVERAGEIFS('Historial Mensual'!$V$2:$V$3601,'Historial Mensual'!$A$2:$A$3601,$A6,'Historial Mensual'!$C$2:$C$3601,$D6) -> 0.029251318 | R6: =SQRT(SUMPRODUCT(('Historial Mensual'!$A$2:$A$3601=A6)*('Historial Mensual'!$C$2:$C$3601=D6)*('Historial Mensual'!$V$2:$V$3601-Q6)^2)/11) -> 0.039086383 | S6: =AVERAGEIFS('Historial Mensual'!$W$2:$W$3601,'Historial Mensual'!$A$2:$A$3601,$A6,'Historial Mensual'!$C$2:$C$3601,$D6) -> 79.428625 | T6: =SUMIFS('Auditoria Cumplimiento'!$J:$J,'Auditoria Cumplimiento'!$A:$A,A6,'Auditoria Cumplimiento'!$B:$B,D6) -> 79.633333 | U6: =AVERAGEIFS('Historial Mensual'!$AA$2:$AA$3601,'Historial Mensual'!$A$2:$A$3601,$A6,'Historial Mensual'!$C$2:$C$3601,$D6) -> 0.113225 | V6: =AVERAGEIFS('Historial Mensual'!$AC$2:$AC$3601,'Historial Mensual'!$A$2:$A$3601,$A6,'Historial Mensual'!$C$2:$C$3601,$D6) -> 0.020275595
A7: PRV-002 | B7: =INDEX('Catalogo Proveedores'!$B$2:$B$101,MATCH(A7,'Catalogo Proveedores'!$A$2:$A$101,0)) -> Distribuidora Resinas de Occidente S.A.P.I. de C.V. | C7: =INDEX('Catalogo Proveedores'!$C$2:$C$101,MATCH(A7,'Catalogo Proveedores'!$A$2:$A$101,0)) -> Materias primas | D7: 2025 | E7: =SUMIFS(Contratos!$C:$C,Contratos!$A:$A,A7,Contratos!$B:$B,D7) -> 59000000 | F7: =SUMIFS('Historial Mensual'!$E$2:$E$3601,'Historial Mensual'!$A$2:$A$3601,$A7,'Historial Mensual'!$C$2:$C$3601,$D7) -> 57623091 | G7: =SUMPRODUCT(('Historial Mensual'!$A$2:$A$3601=A7)*('Historial Mensual'!$C$2:$C$3601=D7)*'Historial Mensual'!$G$2:$G$3601) -> 0.0309 | H7: =AVERAGEIFS('Historial Mensual'!$H$2:$H$3601,'Historial Mensual'!$A$2:$A$3601,$A7,'Historial Mensual'!$C$2:$C$3601,$D7) -> 72.216667 | I7: =AVERAGEIFS('Historial Mensual'!$K$2:$K$3601,'Historial Mensual'!$A$2:$A$3601,$A7,'Historial Mensual'!$C$2:$C$3601,$D7) -> 0.78330833 | J7: =AVERAGEIFS('Historial Mensual'!$L$2:$L$3601,'Historial Mensual'!$A$2:$A$3601,$A7,'Historial Mensual'!$C$2:$C$3601,$D7) -> 0.1146 | K7: =SUMIFS('Historial Mensual'!$M$2:$M$3601,'Historial Mensual'!$A$2:$A$3601,$A7,'Historial Mensual'!$C$2:$C$3601,$D7) -> 9 | L7: =SUMIFS('Historial Mensual'!$N$2:$N$3601,'Historial Mensual'!$A$2:$A$3601,$A7,'Historial Mensual'!$C$2:$C$3601,$D7) -> 6 | M7: =SUMIFS('Historial Mensual'!$O$2:$O$3601,'Historial Mensual'!$A$2:$A$3601,$A7,'Historial Mensual'!$C$2:$C$3601,$D7) -> 213.3 | N7: =AVERAGEIFS('Historial Mensual'!$P$2:$P$3601,'Historial Mensual'!$A$2:$A$3601,$A7,'Historial Mensual'!$C$2:$C$3601,$D7) -> 81.866667 | O7: =SUMIFS('Historial Mensual'!$Q$2:$Q$3601,'Historial Mensual'!$A$2:$A$3601,$A7,'Historial Mensual'!$C$2:$C$3601,$D7) -> 3215966.8 | P7: =SUMIFS('Historial Mensual'!$S$2:$S$3601,'Historial Mensual'!$A$2:$A$3601,$A7,'Historial Mensual'!$C$2:$C$3601,$D7) -> 2468592.9 | Q7: =AVERAGEIFS('Historial Mensual'!$V$2:$V$3601,'Historial Mensual'!$A$2:$A$3601,$A7,'Historial Mensual'!$C$2:$C$3601,$D7) -> -0.043344559 | R7: =SQRT(SUMPRODUCT(('Historial Mensual'!$A$2:$A$3601=A7)*('Historial Mensual'!$C$2:$C$3601=D7)*('Historial Mensual'!$V$2:$V$3601-Q7)^2)/11) -> 0.1992351 | S7: =AVERAGEIFS('Historial Mensual'!$W$2:$W$3601,'Historial Mensual'!$A$2:$A$3601,$A7,'Historial Mensual'!$C$2:$C$3601,$D7) -> 78.429417 | T7: =SUMIFS('Auditoria Cumplimiento'!$J:$J,'Auditoria Cumplimiento'!$A:$A,A7,'Auditoria Cumplimiento'!$B:$B,D7) -> 81.133333 | U7: =AVERAGEIFS('Historial Mensual'!$AA$2:$AA$3601,'Historial Mensual'!$A$2:$A$3601,$A7,'Historial Mensual'!$C$2:$C$3601,$D7) -> 0.0900975 | V7: =AVERAGEIFS('Historial Mensual'!$AC$2:$AC$3601,'Historial Mensual'!$A$2:$A$3601,$A7,'Historial Mensual'!$C$2:$C$3601,$D7) -> -0.050558423
A8: PRV-003 | B8: =INDEX('Catalogo Proveedores'!$B$2:$B$101,MATCH(A8,'Catalogo Proveedores'!$A$2:$A$101,0)) -> Corporativo Metales Unidos S.A. de C.V. | C8: =INDEX('Catalogo Proveedores'!$C$2:$C$101,MATCH(A8,'Catalogo Proveedores'!$A$2:$A$101,0)) -> Materias primas | D8: 2023 | E8: =SUMIFS(Contratos!$C:$C,Contratos!$A:$A,A8,Contratos!$B:$B,D8) -> 49976000 | F8: =SUMIFS('Historial Mensual'!$E$2:$E$3601,'Historial Mensual'!$A$2:$A$3601,$A8,'Historial Mensual'!$C$2:$C$3601,$D8) -> 50271630 | G8: =SUMPRODUCT(('Historial Mensual'!$A$2:$A$3601=A8)*('Historial Mensual'!$C$2:$C$3601=D8)*'Historial Mensual'!$G$2:$G$3601) -> 0.0457 | H8: =AVERAGEIFS('Historial Mensual'!$H$2:$H$3601,'Historial Mensual'!$A$2:$A$3601,$A8,'Historial Mensual'!$C$2:$C$3601,$D8) -> 72.908333 | I8: =AVERAGEIFS('Historial Mensual'!$K$2:$K$3601,'Historial Mensual'!$A$2:$A$3601,$A8,'Historial Mensual'!$C$2:$C$3601,$D8) -> 0.89055833 | J8: =AVERAGEIFS('Historial Mensual'!$L$2:$L$3601,'Historial Mensual'!$A$2:$A$3601,$A8,'Historial Mensual'!$C$2:$C$3601,$D8) -> 0.097158333 | K8: =SUMIFS('Historial Mensual'!$M$2:$M$3601,'Historial Mensual'!$A$2:$A$3601,$A8,'Historial Mensual'!$C$2:$C$3601,$D8) -> 9 | L8: =SUMIFS('Historial Mensual'!$N$2:$N$3601,'Historial Mensual'!$A$2:$A$3601,$A8,'Historial Mensual'!$C$2:$C$3601,$D8) -> 3 | M8: =SUMIFS('Historial Mensual'!$O$2:$O$3601,'Historial Mensual'!$A$2:$A$3601,$A8,'Historial Mensual'!$C$2:$C$3601,$D8) -> 23.2 | N8: =AVERAGEIFS('Historial Mensual'!$P$2:$P$3601,'Historial Mensual'!$A$2:$A$3601,$A8,'Historial Mensual'!$C$2:$C$3601,$D8) -> 78.575 | O8: =SUMIFS('Historial Mensual'!$Q$2:$Q$3601,'Historial Mensual'!$A$2:$A$3601,$A8,'Historial Mensual'!$C$2:$C$3601,$D8) -> 960628.11 | P8: =SUMIFS('Historial Mensual'!$S$2:$S$3601,'Historial Mensual'!$A$2:$A$3601,$A8,'Historial Mensual'!$C$2:$C$3601,$D8) -> 1687261.4 | Q8: =AVERAGEIFS('Historial Mensual'!$V$2:$V$3601,'Historial Mensual'!$A$2:$A$3601,$A8,'Historial Mensual'!$C$2:$C$3601,$D8) -> 0.036573362 | R8: =SQRT(SUMPRODUCT(('Historial Mensual'!$A$2:$A$3601=A8)*('Historial Mensual'!$C$2:$C$3601=D8)*('Historial Mensual'!$V$2:$V$3601-Q8)^2)/11) -> 0.051797337 | S8: =AVERAGEIFS('Historial Mensual'!$W$2:$W$3601,'Historial Mensual'!$A$2:$A$3601,$A8,'Historial Mensual'!$C$2:$C$3601,$D8) -> 81.492292 | T8: =SUMIFS('Auditoria Cumplimiento'!$J:$J,'Auditoria Cumplimiento'!$A:$A,A8,'Auditoria Cumplimiento'!$B:$B,D8) -> 79.783333 | U8: =AVERAGEIFS('Historial Mensual'!$AA$2:$AA$3601,'Historial Mensual'!$A$2:$A$3601,$A8,'Historial Mensual'!$C$2:$C$3601,$D8) -> 0.14489417 | V8: =AVERAGEIFS('Historial Mensual'!$AC$2:$AC$3601,'Historial Mensual'!$A$2:$A$3601,$A8,'Historial Mensual'!$C$2:$C$3601,$D8) -> 0.02523385
A9: PRV-003 | B9: =INDEX('Catalogo Proveedores'!$B$2:$B$101,MATCH(A9,'Catalogo Proveedores'!$A$2:$A$101,0)) -> Corporativo Metales Unidos S.A. de C.V. | C9: =INDEX('Catalogo Proveedores'!$C$2:$C$101,MATCH(A9,'Catalogo Proveedores'!$A$2:$A$101,0)) -> Materias primas | D9: 2024 | E9: =SUMIFS(Contratos!$C:$C,Contratos!$A:$A,A9,Contratos!$B:$B,D9) -> 47244000 | F9: =SUMIFS('Historial Mensual'!$E$2:$E$3601,'Historial Mensual'!$A$2:$A$3601,$A9,'Historial Mensual'!$C$2:$C$3601,$D9) -> 48313074 | G9: =SUMPRODUCT(('Historial Mensual'!$A$2:$A$3601=A9)*('Historial Mensual'!$C$2:$C$3601=D9)*'Historial Mensual'!$G$2:$G$3601) -> 0.0511 | H9: =AVERAGEIFS('Historial Mensual'!$H$2:$H$3601,'Historial Mensual'!$A$2:$A$3601,$A9,'Historial Mensual'!$C$2:$C$3601,$D9) -> 73.95 | I9: =AVERAGEIFS('Historial Mensual'!$K$2:$K$3601,'Historial Mensual'!$A$2:$A$3601,$A9,'Historial Mensual'!$C$2:$C$3601,$D9) -> 0.90179167 | J9: =AVERAGEIFS('Historial Mensual'!$L$2:$L$3601,'Historial Mensual'!$A$2:$A$3601,$A9,'Historial Mensual'!$C$2:$C$3601,$D9) -> 0.091958333 | K9: =SUMIFS('Historial Mensual'!$M$2:$M$3601,'Historial Mensual'!$A$2:$A$3601,$A9,'Historial Mensual'!$C$2:$C$3601,$D9) -> 11 | L9: =SUMIFS('Historial Mensual'!$N$2:$N$3601,'Historial Mensual'!$A$2:$A$3601,$A9,'Historial Mensual'!$C$2:$C$3601,$D9) -> 7 | M9: =SUMIFS('Historial Mensual'!$O$2:$O$3601,'Historial Mensual'!$A$2:$A$3601,$A9,'Historial Mensual'!$C$2:$C$3601,$D9) -> 300 | N9: =AVERAGEIFS('Historial Mensual'!$P$2:$P$3601,'Historial Mensual'!$A$2:$A$3601,$A9,'Historial Mensual'!$C$2:$C$3601,$D9) -> 77.691667 | O9: =SUMIFS('Historial Mensual'!$Q$2:$Q$3601,'Historial Mensual'!$A$2:$A$3601,$A9,'Historial Mensual'!$C$2:$C$3601,$D9) -> 4802067.7 | P9: =SUMIFS('Historial Mensual'!$S$2:$S$3601,'Historial Mensual'!$A$2:$A$3601,$A9,'Historial Mensual'!$C$2:$C$3601,$D9) -> 1484770.2 | Q9: =AVERAGEIFS('Historial Mensual'!$V$2:$V$3601,'Historial Mensual'!$A$2:$A$3601,$A9,'Historial Mensual'!$C$2:$C$3601,$D9) -> -0.035488151 | R9: =SQRT(SUMPRODUCT(('Historial Mensual'!$A$2:$A$3601=A9)*('Historial Mensual'!$C$2:$C$3601=D9)*('Historial Mensual'!$V$2:$V$3601-Q9)^2)/11) -> 0.18033713 | S9: =AVERAGEIFS('Historial Mensual'!$W$2:$W$3601,'Historial Mensual'!$A$2:$A$3601,$A9,'Historial Mensual'!$C$2:$C$3601,$D9) -> 82.095208 | T9: =SUMIFS('Auditoria Cumplimiento'!$J:$J,'Auditoria Cumplimiento'!$A:$A,A9,'Auditoria Cumplimiento'!$B:$B,D9) -> 76.083333 | U9: =AVERAGEIFS('Historial Mensual'!$AA$2:$AA$3601,'Historial Mensual'!$A$2:$A$3601,$A9,'Historial Mensual'!$C$2:$C$3601,$D9) -> 0.13737333 | V9: =AVERAGEIFS('Historial Mensual'!$AC$2:$AC$3601,'Historial Mensual'!$A$2:$A$3601,$A9,'Historial Mensual'!$C$2:$C$3601,$D9) -> -0.046271501
A10: PRV-003 | B10: =INDEX('Catalogo Proveedores'!$B$2:$B$101,MATCH(A10,'Catalogo Proveedores'!$A$2:$A$101,0)) -> Corporativo Metales Unidos S.A. de C.V. | C10: =INDEX('Catalogo Proveedores'!$C$2:$C$101,MATCH(A10,'Catalogo Proveedores'!$A$2:$A$101,0)) -> Materias primas | D10: 2025 | E10: =SUMIFS(Contratos!$C:$C,Contratos!$A:$A,A10,Contratos!$B:$B,D10) -> 52773000 | F10: =SUMIFS('Historial Mensual'!$E$2:$E$3601,'Historial Mensual'!$A$2:$A$3601,$A10,'Historial Mensual'!$C$2:$C$3601,$D10) -> 52951110 | G10: =SUMPRODUCT(('Historial Mensual'!$A$2:$A$3601=A10)*('Historial Mensual'!$C$2:$C$3601=D10)*'Historial Mensual'!$G$2:$G$3601) -> 0.0577 | H10: =AVERAGEIFS('Historial Mensual'!$H$2:$H$3601,'Historial Mensual'!$A$2:$A$3601,$A10,'Historial Mensual'!$C$2:$C$3601,$D10) -> 74.625 | I10: =AVERAGEIFS('Historial Mensual'!$K$2:$K$3601,'Historial Mensual'!$A$2:$A$3601,$A10,'Historial Mensual'!$C$2:$C$3601,$D10) -> 0.88134167 | J10: =AVERAGEIFS('Historial Mensual'!$L$2:$L$3601,'Historial Mensual'!$A$2:$A$3601,$A10,'Historial Mensual'!$C$2:$C$3601,$D10) -> 0.098825 | K10: =SUMIFS('Historial Mensual'!$M$2:$M$3601,'Historial Mensual'!$A$2:$A$3601,$A10,'Historial Mensual'!$C$2:$C$3601,$D10) -> 10 | L10: =SUMIFS('Historial Mensual'!$N$2:$N$3601,'Historial Mensual'!$A$2:$A$3601,$A10,'Historial Mensual'!$C$2:$C$3601,$D10) -> 0 | M10: =SUMIFS('Historial Mensual'!$O$2:$O$3601,'Historial Mensual'!$A$2:$A$3601,$A10,'Historial Mensual'!$C$2:$C$3601,$D10) -> 0 | N10: =AVERAGEIFS('Historial Mensual'!$P$2:$P$3601,'Historial Mensual'!$A$2:$A$3601,$A10,'Historial Mensual'!$C$2:$C$3601,$D10) -> 77.366667 | O10: =SUMIFS('Historial Mensual'!$Q$2:$Q$3601,'Historial Mensual'!$A$2:$A$3601,$A10,'Historial Mensual'!$C$2:$C$3601,$D10) -> 601694.92 | P10: =SUMIFS('Historial Mensual'!$S$2:$S$3601,'Historial Mensual'!$A$2:$A$3601,$A10,'Historial Mensual'!$C$2:$C$3601,$D10) -> 1812723.5 | Q10: =AVERAGEIFS('Historial Mensual'!$V$2:$V$3601,'Historial Mensual'!$A$2:$A$3601,$A10,'Historial Mensual'!$C$2:$C$3601,$D10) -> 0.047214759 | R10: =SQRT(SUMPRODUCT(('Historial Mensual'!$A$2:$A$3601=A10)*('Historial Mensual'!$C$2:$C$3601=D10)*('Historial Mensual'!$V$2:$V$3601-Q10)^2)/11) -> 0.043678032 | S10: =AVERAGEIFS('Historial Mensual'!$W$2:$W$3601,'Historial Mensual'!$A$2:$A$3601,$A10,'Historial Mensual'!$C$2:$C$3601,$D10) -> 81.549958 | T10: =SUMIFS('Auditoria Cumplimiento'!$J:$J,'Auditoria Cumplimiento'!$A:$A,A10,'Auditoria Cumplimiento'!$B:$B,D10) -> 80.383333 | U10: =AVERAGEIFS('Historial Mensual'!$AA$2:$AA$3601,'Historial Mensual'!$A$2:$A$3601,$A10,'Historial Mensual'!$C$2:$C$3601,$D10) -> 0.11161083 | V10: =AVERAGEIFS('Historial Mensual'!$AC$2:$AC$3601,'Historial Mensual'!$A$2:$A$3601,$A10,'Historial Mensual'!$C$2:$C$3601,$D10) -> 0.038360094
A11: PRV-004 | B11: =INDEX('Catalogo Proveedores'!$B$2:$B$101,MATCH(A11,'Catalogo Proveedores'!$A$2:$A$101,0)) -> Proveedora Polímeros del Golfo S. de R.L. de C.V. | C11: =INDEX('Catalogo Proveedores'!$C$2:$C$101,MATCH(A11,'Catalogo Proveedores'!$A$2:$A$101,0)) -> Materias primas | D11: 2023 | E11: =SUMIFS(Contratos!$C:$C,Contratos!$A:$A,A11,Contratos!$B:$B,D11) -> 20298000 | F11: =SUMIFS('Historial Mensual'!$E$2:$E$3601,'Historial Mensual'!$A$2:$A$3601,$A11,'Historial Mensual'!$C$2:$C$3601,$D11) -> 20549295 | G11: =SUMPRODUCT(('Historial Mensual'!$A$2:$A$3601=A11)*('Historial Mensual'!$C$2:$C$3601=D11)*'Historial Mensual'!$G$2:$G$3601) -> 0.0786 | H11: =AVERAGEIFS('Historial Mensual'!$H$2:$H$3601,'Historial Mensual'!$A$2:$A$3601,$A11,'Historial Mensual'!$C$2:$C$3601,$D11) -> 90.108333 | I11: =AVERAGEIFS('Historial Mensual'!$K$2:$K$3601,'Historial Mensual'!$A$2:$A$3601,$A11,'Historial Mensual'!$C$2:$C$3601,$D11) -> 0.8857 | J11: =AVERAGEIFS('Historial Mensual'!$L$2:$L$3601,'Historial Mensual'!$A$2:$A$3601,$A11,'Historial Mensual'!$C$2:$C$3601,$D11) -> 0.032125 | K11: =SUMIFS('Historial Mensual'!$M$2:$M$3601,'Historial Mensual'!$A$2:$A$3601,$A11,'Historial Mensual'!$C$2:$C$3601,$D11) -> 11 | L11: =SUMIFS('Historial Mensual'!$N$2:$N$3601,'Historial Mensual'!$A$2:$A$3601,$A11,'Historial Mensual'!$C$2:$C$3601,$D11) -> 6 | M11: =SUMIFS('Historial Mensual'!$O$2:$O$3601,'Historial Mensual'!$A$2:$A$3601,$A11,'Historial Mensual'!$C$2:$C$3601,$D11) -> 205.2 | N11: =AVERAGEIFS('Historial Mensual'!$P$2:$P$3601,'Historial Mensual'!$A$2:$A$3601,$A11,'Historial Mensual'!$C$2:$C$3601,$D11) -> 75.108333 | O11: =SUMIFS('Historial Mensual'!$Q$2:$Q$3601,'Historial Mensual'!$A$2:$A$3601,$A11,'Historial Mensual'!$C$2:$C$3601,$D11) -> 1319501.3 | P11: =SUMIFS('Historial Mensual'!$S$2:$S$3601,'Historial Mensual'!$A$2:$A$3601,$A11,'Historial Mensual'!$C$2:$C$3601,$D11) -> 247403.6 | Q11: =AVERAGEIFS('Historial Mensual'!$V$2:$V$3601,'Historial Mensual'!$A$2:$A$3601,$A11,'Historial Mensual'!$C$2:$C$3601,$D11) -> 0.014707454 | R11: =SQRT(SUMPRODUCT(('Historial Mensual'!$A$2:$A$3601=A11)*('Historial Mensual'!$C$2:$C$3601=D11)*('Historial Mensual'!$V$2:$V$3601-Q11)^2)/11) -> 0.17175553 | S11: =AVERAGEIFS('Historial Mensual'!$W$2:$W$3601,'Historial Mensual'!$A$2:$A$3601,$A11,'Historial Mensual'!$C$2:$C$3601,$D11) -> 87.648708 | T11: =SUMIFS('Auditoria Cumplimiento'!$J:$J,'Auditoria Cumplimiento'!$A:$A,A11,'Auditoria Cumplimiento'!$B:$B,D11) -> 76.1 | U11: =AVERAGEIFS('Historial Mensual'!$AA$2:$AA$3601,'Historial Mensual'!$A$2:$A$3601,$A11,'Historial Mensual'!$C$2:$C$3601,$D11) -> 0.14080583 | V11: =AVERAGEIFS('Historial Mensual'!$AC$2:$AC$3601,'Historial Mensual'!$A$2:$A$3601,$A11,'Historial Mensual'!$C$2:$C$3601,$D11) -> 0.003669443
A12: PRV-004 | B12: =INDEX('Catalogo Proveedores'!$B$2:$B$101,MATCH(A12,'Catalogo Proveedores'!$A$2:$A$101,0)) -> Proveedora Polímeros del Golfo S. de R.L. de C.V. | C12: =INDEX('Catalogo Proveedores'!$C$2:$C$101,MATCH(A12,'Catalogo Proveedores'!$A$2:$A$101,0)) -> Materias primas | D12: 2024 | E12: =SUMIFS(Contratos!$C:$C,Contratos!$A:$A,A12,Contratos!$B:$B,D12) -> 22147000 | F12: =SUMIFS('Historial Mensual'!$E$2:$E$3601,'Historial Mensual'!$A$2:$A$3601,$A12,'Historial Mensual'!$C$2:$C$3601,$D12) -> 21685991 | G12: =SUMPRODUCT(('Historial Mensual'!$A$2:$A$3601=A12)*('Historial Mensual'!$C$2:$C$3601=D12)*'Historial Mensual'!$G$2:$G$3601) -> 0.0491 | H12: =AVERAGEIFS('Historial Mensual'!$H$2:$H$3601,'Historial Mensual'!$A$2:$A$3601,$A12,'Historial Mensual'!$C$2:$C$3601,$D12) -> 81.841667 | I12: =AVERAGEIFS('Historial Mensual'!$K$2:$K$3601,'Historial Mensual'!$A$2:$A$3601,$A12,'Historial Mensual'!$C$2:$C$3601,$D12) -> 0.88624167 | J12: =AVERAGEIFS('Historial Mensual'!$L$2:$L$3601,'Historial Mensual'!$A$2:$A$3601,$A12,'Historial Mensual'!$C$2:$C$3601,$D12) -> 0.064033333 | K12: =SUMIFS('Historial Mensual'!$M$2:$M$3601,'Historial Mensual'!$A$2:$A$3601,$A12,'Historial Mensual'!$C$2:$C$3601,$D12) -> 9 | L12: =SUMIFS('Historial Mensual'!$N$2:$N$3601,'Historial Mensual'!$A$2:$A$3601,$A12,'Historial Mensual'!$C$2:$C$3601,$D12) -> 4 | M12: =SUMIFS('Historial Mensual'!$O$2:$O$3601,'Historial Mensual'!$A$2:$A$3601,$A12,'Historial Mensual'!$C$2:$C$3601,$D12) -> 114.1 | N12: =AVERAGEIFS('Historial Mensual'!$P$2:$P$3601,'Historial Mensual'!$A$2:$A$3601,$A12,'Historial Mensual'!$C$2:$C$3601,$D12) -> 76.991667 | O12: =SUMIFS('Historial Mensual'!$Q$2:$Q$3601,'Historial Mensual'!$A$2:$A$3601,$A12,'Historial Mensual'!$C$2:$C$3601,$D12) -> 829455.19 | P12: =SUMIFS('Historial Mensual'!$S$2:$S$3601,'Historial Mensual'!$A$2:$A$3601,$A12,'Historial Mensual'!$C$2:$C$3601,$D12) -> 471115.59 | Q12: =AVERAGEIFS('Historial Mensual'!$V$2:$V$3601,'Historial Mensual'!$A$2:$A$3601,$A12,'Historial Mensual'!$C$2:$C$3601,$D12) -> 0.044633433 | R12: =SQRT(SUMPRODUCT(('Historial Mensual'!$A$2:$A$3601=A12)*('Historial Mensual'!$C$2:$C$3601=D12)*('Historial Mensual'!$V$2:$V$3601-Q12)^2)/11) -> 0.087666783 | S12: =AVERAGEIFS('Historial Mensual'!$W$2:$W$3601,'Historial Mensual'!$A$2:$A$3601,$A12,'Historial Mensual'!$C$2:$C$3601,$D12) -> 84.669667 | T12: =SUMIFS('Auditoria Cumplimiento'!$J:$J,'Auditoria Cumplimiento'!$A:$A,A12,'Auditoria Cumplimiento'!$B:$B,D12) -> 75.733333 | U12: =AVERAGEIFS('Historial Mensual'!$AA$2:$AA$3601,'Historial Mensual'!$A$2:$A$3601,$A12,'Historial Mensual'!$C$2:$C$3601,$D12) -> 0.133635 | V12: =AVERAGEIFS('Historial Mensual'!$AC$2:$AC$3601,'Historial Mensual'!$A$2:$A$3601,$A12,'Historial Mensual'!$C$2:$C$3601,$D12) -> 0.034128232
